[2023-08-02T08:30:37.040+0000] {taskinstance.py:1165} INFO - Dependencies all met for <TaskInstance: xcom_dag.t1 manual__2023-08-02T08:30:36.437524+00:00 [queued]>
[2023-08-02T08:30:37.046+0000] {taskinstance.py:1165} INFO - Dependencies all met for <TaskInstance: xcom_dag.t1 manual__2023-08-02T08:30:36.437524+00:00 [queued]>
[2023-08-02T08:30:37.046+0000] {taskinstance.py:1362} INFO - 
--------------------------------------------------------------------------------
[2023-08-02T08:30:37.047+0000] {taskinstance.py:1363} INFO - Starting attempt 1 of 1
[2023-08-02T08:30:37.047+0000] {taskinstance.py:1364} INFO - 
--------------------------------------------------------------------------------
[2023-08-02T08:30:37.054+0000] {taskinstance.py:1383} INFO - Executing <Task(PythonOperator): t1> on 2023-08-02 08:30:36.437524+00:00
[2023-08-02T08:30:37.059+0000] {standard_task_runner.py:55} INFO - Started process 14558 to run task
[2023-08-02T08:30:37.063+0000] {standard_task_runner.py:82} INFO - Running: ['***', 'tasks', 'run', 'xcom_dag', 't1', 'manual__2023-08-02T08:30:36.437524+00:00', '--job-id', '325', '--raw', '--subdir', 'DAGS_FOLDER/xcom_dag.py', '--cfg-path', '/tmp/tmp00utyv1j']
[2023-08-02T08:30:37.063+0000] {standard_task_runner.py:83} INFO - Job 325: Subtask t1
[2023-08-02T08:30:37.113+0000] {task_command.py:376} INFO - Running <TaskInstance: xcom_dag.t1 manual__2023-08-02T08:30:36.437524+00:00 [running]> on host 45dcf9d0cab9
[2023-08-02T08:30:37.162+0000] {taskinstance.py:1592} INFO - Exporting the following env vars:
AIRFLOW_CTX_DAG_OWNER=***
AIRFLOW_CTX_DAG_ID=xcom_dag
AIRFLOW_CTX_TASK_ID=t1
AIRFLOW_CTX_EXECUTION_DATE=2023-08-02T08:30:36.437524+00:00
AIRFLOW_CTX_TRY_NUMBER=1
AIRFLOW_CTX_DAG_RUN_ID=manual__2023-08-02T08:30:36.437524+00:00
[2023-08-02T08:30:37.163+0000] {taskinstance.py:1851} ERROR - Task failed with exception
Traceback (most recent call last):
  File "/home/airflow/.local/lib/python3.7/site-packages/airflow/operators/python.py", line 175, in execute
    return_value = self.execute_callable()
  File "/home/airflow/.local/lib/python3.7/site-packages/airflow/operators/python.py", line 193, in execute_callable
    return self.python_callable(*self.op_args, **self.op_kwargs)
  File "/opt/airflow/dags/xcom_dag.py", line 8, in _t1
    ti.xcom_puch(key='my_key', value=42)
AttributeError: 'TaskInstance' object has no attribute 'xcom_puch'
[2023-08-02T08:30:37.172+0000] {taskinstance.py:1406} INFO - Marking task as FAILED. dag_id=xcom_dag, task_id=t1, execution_date=20230802T083036, start_date=20230802T083037, end_date=20230802T083037
[2023-08-02T08:30:37.179+0000] {standard_task_runner.py:105} ERROR - Failed to execute job 325 for task t1 ('TaskInstance' object has no attribute 'xcom_puch'; 14558)
[2023-08-02T08:30:37.196+0000] {local_task_job.py:164} INFO - Task exited with return code 1
[2023-08-02T08:30:37.215+0000] {local_task_job.py:273} INFO - 0 downstream tasks scheduled from follow-on schedule check
