[2023-08-02T08:53:17.868+0000] {taskinstance.py:1165} INFO - Dependencies all met for <TaskInstance: xcom_dag.t1 manual__2023-08-02T08:53:16.999812+00:00 [queued]>
[2023-08-02T08:53:17.875+0000] {taskinstance.py:1165} INFO - Dependencies all met for <TaskInstance: xcom_dag.t1 manual__2023-08-02T08:53:16.999812+00:00 [queued]>
[2023-08-02T08:53:17.875+0000] {taskinstance.py:1362} INFO - 
--------------------------------------------------------------------------------
[2023-08-02T08:53:17.876+0000] {taskinstance.py:1363} INFO - Starting attempt 1 of 1
[2023-08-02T08:53:17.876+0000] {taskinstance.py:1364} INFO - 
--------------------------------------------------------------------------------
[2023-08-02T08:53:17.884+0000] {taskinstance.py:1383} INFO - Executing <Task(PythonOperator): t1> on 2023-08-02 08:53:16.999812+00:00
[2023-08-02T08:53:17.889+0000] {standard_task_runner.py:55} INFO - Started process 1059 to run task
[2023-08-02T08:53:17.892+0000] {standard_task_runner.py:82} INFO - Running: ['***', 'tasks', 'run', 'xcom_dag', 't1', 'manual__2023-08-02T08:53:16.999812+00:00', '--job-id', '329', '--raw', '--subdir', 'DAGS_FOLDER/xcom_dag.py', '--cfg-path', '/tmp/tmp0pjj0s24']
[2023-08-02T08:53:17.893+0000] {standard_task_runner.py:83} INFO - Job 329: Subtask t1
[2023-08-02T08:53:17.946+0000] {task_command.py:376} INFO - Running <TaskInstance: xcom_dag.t1 manual__2023-08-02T08:53:16.999812+00:00 [running]> on host c84be6b275ee
[2023-08-02T08:53:18.008+0000] {taskinstance.py:1592} INFO - Exporting the following env vars:
AIRFLOW_CTX_DAG_OWNER=***
AIRFLOW_CTX_DAG_ID=xcom_dag
AIRFLOW_CTX_TASK_ID=t1
AIRFLOW_CTX_EXECUTION_DATE=2023-08-02T08:53:16.999812+00:00
AIRFLOW_CTX_TRY_NUMBER=1
AIRFLOW_CTX_DAG_RUN_ID=manual__2023-08-02T08:53:16.999812+00:00
[2023-08-02T08:53:18.009+0000] {taskinstance.py:1851} ERROR - Task failed with exception
Traceback (most recent call last):
  File "/home/airflow/.local/lib/python3.7/site-packages/airflow/operators/python.py", line 175, in execute
    return_value = self.execute_callable()
  File "/home/airflow/.local/lib/python3.7/site-packages/airflow/operators/python.py", line 193, in execute_callable
    return self.python_callable(*self.op_args, **self.op_kwargs)
  File "/opt/airflow/dags/xcom_dag.py", line 8, in _t1
    ti.xcom_puch(key='my_key', value=42)
AttributeError: 'TaskInstance' object has no attribute 'xcom_puch'
[2023-08-02T08:53:18.019+0000] {taskinstance.py:1406} INFO - Marking task as FAILED. dag_id=xcom_dag, task_id=t1, execution_date=20230802T085316, start_date=20230802T085317, end_date=20230802T085318
[2023-08-02T08:53:18.028+0000] {standard_task_runner.py:105} ERROR - Failed to execute job 329 for task t1 ('TaskInstance' object has no attribute 'xcom_puch'; 1059)
[2023-08-02T08:53:18.066+0000] {local_task_job.py:164} INFO - Task exited with return code 1
[2023-08-02T08:53:18.090+0000] {local_task_job.py:273} INFO - 0 downstream tasks scheduled from follow-on schedule check
